2020-01-09 09:04:29,958 ERROR: Exception on /exercises/Pushups [POST] [in /Users/danielvaroli/Desktop/personal_website/workout_app/venv/lib/python3.7/site-packages/flask/app.py:1891]
Traceback (most recent call last):
  File "/Users/danielvaroli/Desktop/personal_website/workout_app/venv/lib/python3.7/site-packages/flask/app.py", line 2446, in wsgi_app
    response = self.full_dispatch_request()
  File "/Users/danielvaroli/Desktop/personal_website/workout_app/venv/lib/python3.7/site-packages/flask/app.py", line 1951, in full_dispatch_request
    rv = self.handle_user_exception(e)
  File "/Users/danielvaroli/Desktop/personal_website/workout_app/venv/lib/python3.7/site-packages/flask/app.py", line 1820, in handle_user_exception
    reraise(exc_type, exc_value, tb)
  File "/Users/danielvaroli/Desktop/personal_website/workout_app/venv/lib/python3.7/site-packages/flask/_compat.py", line 39, in reraise
    raise value
  File "/Users/danielvaroli/Desktop/personal_website/workout_app/venv/lib/python3.7/site-packages/flask/app.py", line 1949, in full_dispatch_request
    rv = self.dispatch_request()
  File "/Users/danielvaroli/Desktop/personal_website/workout_app/venv/lib/python3.7/site-packages/flask/app.py", line 1935, in dispatch_request
    return self.view_functions[rule.endpoint](**req.view_args)
  File "/Users/danielvaroli/Desktop/personal_website/workout_app/venv/lib/python3.7/site-packages/flask_login/utils.py", line 261, in decorated_view
    return func(*args, **kwargs)
  File "/Users/danielvaroli/Desktop/personal_website/workout_app/app/main/routes.py", line 59, in exercise
    if form.validate_on_submit():
  File "/Users/danielvaroli/Desktop/personal_website/workout_app/venv/lib/python3.7/site-packages/flask_wtf/form.py", line 101, in validate_on_submit
    return self.is_submitted() and self.validate()
  File "/Users/danielvaroli/Desktop/personal_website/workout_app/venv/lib/python3.7/site-packages/wtforms/form.py", line 310, in validate
    return super(Form, self).validate(extra)
  File "/Users/danielvaroli/Desktop/personal_website/workout_app/venv/lib/python3.7/site-packages/wtforms/form.py", line 152, in validate
    if not field.validate(self, extra):
  File "/Users/danielvaroli/Desktop/personal_website/workout_app/venv/lib/python3.7/site-packages/wtforms/fields/core.py", line 206, in validate
    stop_validation = self._run_validation_chain(form, chain)
  File "/Users/danielvaroli/Desktop/personal_website/workout_app/venv/lib/python3.7/site-packages/wtforms/fields/core.py", line 226, in _run_validation_chain
    validator(form, self)
TypeError: __init__() takes from 1 to 2 positional arguments but 3 were given
2020-01-09 09:06:39,650 ERROR: Exception on /exercises/Pushups [POST] [in /Users/danielvaroli/Desktop/personal_website/workout_app/venv/lib/python3.7/site-packages/flask/app.py:1891]
Traceback (most recent call last):
  File "/Users/danielvaroli/Desktop/personal_website/workout_app/venv/lib/python3.7/site-packages/flask/app.py", line 2446, in wsgi_app
    response = self.full_dispatch_request()
  File "/Users/danielvaroli/Desktop/personal_website/workout_app/venv/lib/python3.7/site-packages/flask/app.py", line 1951, in full_dispatch_request
    rv = self.handle_user_exception(e)
  File "/Users/danielvaroli/Desktop/personal_website/workout_app/venv/lib/python3.7/site-packages/flask/app.py", line 1820, in handle_user_exception
    reraise(exc_type, exc_value, tb)
  File "/Users/danielvaroli/Desktop/personal_website/workout_app/venv/lib/python3.7/site-packages/flask/_compat.py", line 39, in reraise
    raise value
  File "/Users/danielvaroli/Desktop/personal_website/workout_app/venv/lib/python3.7/site-packages/flask/app.py", line 1949, in full_dispatch_request
    rv = self.dispatch_request()
  File "/Users/danielvaroli/Desktop/personal_website/workout_app/venv/lib/python3.7/site-packages/flask/app.py", line 1935, in dispatch_request
    return self.view_functions[rule.endpoint](**req.view_args)
  File "/Users/danielvaroli/Desktop/personal_website/workout_app/venv/lib/python3.7/site-packages/flask_login/utils.py", line 261, in decorated_view
    return func(*args, **kwargs)
  File "/Users/danielvaroli/Desktop/personal_website/workout_app/app/main/routes.py", line 59, in exercise
    if form.validate_on_submit():
  File "/Users/danielvaroli/Desktop/personal_website/workout_app/venv/lib/python3.7/site-packages/flask_wtf/form.py", line 101, in validate_on_submit
    return self.is_submitted() and self.validate()
  File "/Users/danielvaroli/Desktop/personal_website/workout_app/venv/lib/python3.7/site-packages/wtforms/form.py", line 310, in validate
    return super(Form, self).validate(extra)
  File "/Users/danielvaroli/Desktop/personal_website/workout_app/venv/lib/python3.7/site-packages/wtforms/form.py", line 152, in validate
    if not field.validate(self, extra):
  File "/Users/danielvaroli/Desktop/personal_website/workout_app/venv/lib/python3.7/site-packages/wtforms/fields/core.py", line 206, in validate
    stop_validation = self._run_validation_chain(form, chain)
  File "/Users/danielvaroli/Desktop/personal_website/workout_app/venv/lib/python3.7/site-packages/wtforms/fields/core.py", line 226, in _run_validation_chain
    validator(form, self)
TypeError: __init__() takes from 1 to 2 positional arguments but 3 were given
2020-01-09 09:08:54,189 INFO: Workout App startup [in /Users/danielvaroli/Desktop/personal_website/workout_app/app/__init__.py:74]
2020-01-09 09:09:57,274 INFO: Workout App startup [in /Users/danielvaroli/Desktop/personal_website/workout_app/app/__init__.py:74]
2020-01-09 09:46:55,270 INFO: Workout App startup [in /Users/danielvaroli/Desktop/personal_website/workout_app/app/__init__.py:74]
2020-01-09 09:46:56,386 ERROR: Exception on /index [GET] [in /Users/danielvaroli/Desktop/personal_website/workout_app/venv/lib/python3.7/site-packages/flask/app.py:1891]
Traceback (most recent call last):
  File "/Users/danielvaroli/Desktop/personal_website/workout_app/venv/lib/python3.7/site-packages/flask/app.py", line 2446, in wsgi_app
    response = self.full_dispatch_request()
  File "/Users/danielvaroli/Desktop/personal_website/workout_app/venv/lib/python3.7/site-packages/flask/app.py", line 1951, in full_dispatch_request
    rv = self.handle_user_exception(e)
  File "/Users/danielvaroli/Desktop/personal_website/workout_app/venv/lib/python3.7/site-packages/flask/app.py", line 1820, in handle_user_exception
    reraise(exc_type, exc_value, tb)
  File "/Users/danielvaroli/Desktop/personal_website/workout_app/venv/lib/python3.7/site-packages/flask/_compat.py", line 39, in reraise
    raise value
  File "/Users/danielvaroli/Desktop/personal_website/workout_app/venv/lib/python3.7/site-packages/flask/app.py", line 1949, in full_dispatch_request
    rv = self.dispatch_request()
  File "/Users/danielvaroli/Desktop/personal_website/workout_app/venv/lib/python3.7/site-packages/flask/app.py", line 1935, in dispatch_request
    return self.view_functions[rule.endpoint](**req.view_args)
  File "/Users/danielvaroli/Desktop/personal_website/workout_app/venv/lib/python3.7/site-packages/flask_login/utils.py", line 261, in decorated_view
    return func(*args, **kwargs)
  File "/Users/danielvaroli/Desktop/personal_website/workout_app/app/main/routes.py", line 39, in index
    return render_template('index.html',title=_('Home'),form=form, exercises=exercises)
  File "/Users/danielvaroli/Desktop/personal_website/workout_app/venv/lib/python3.7/site-packages/flask/templating.py", line 140, in render_template
    ctx.app,
  File "/Users/danielvaroli/Desktop/personal_website/workout_app/venv/lib/python3.7/site-packages/flask/templating.py", line 120, in _render
    rv = template.render(context)
  File "/Users/danielvaroli/Desktop/personal_website/workout_app/venv/lib/python3.7/site-packages/jinja2/asyncsupport.py", line 76, in render
    return original_render(self, *args, **kwargs)
  File "/Users/danielvaroli/Desktop/personal_website/workout_app/venv/lib/python3.7/site-packages/jinja2/environment.py", line 1008, in render
    return self.environment.handle_exception(exc_info, True)
  File "/Users/danielvaroli/Desktop/personal_website/workout_app/venv/lib/python3.7/site-packages/jinja2/environment.py", line 780, in handle_exception
    reraise(exc_type, exc_value, tb)
  File "/Users/danielvaroli/Desktop/personal_website/workout_app/venv/lib/python3.7/site-packages/jinja2/_compat.py", line 37, in reraise
    raise value.with_traceback(tb)
  File "/Users/danielvaroli/Desktop/personal_website/workout_app/app/templates/index.html", line 2, in top-level template code
    {% import 'bootstrap/wtf.html' as wtf %}
jinja2.exceptions.TemplateRuntimeError: extended multiple times
